<robot name="rover">

<link name="body">
<visual>
<origin xyz="-0.19343228599428496928 0.14395944821783071554 0.26237109907984806911" rpy="-1.5707963267948983344 -3.3355470534782881752e-15 -9.5394697344059988075e-16" />
<geometry>
<mesh filename="package://rover_description/rover_desc/parts/body.stl"/>
</geometry>
<material name="body_material">
<color rgba="0.62745098039215685404 0.62745098039215685404 0.62745098039215685404 1.0"/>
</material>
</visual>
<collision>
<origin xyz="-0.19343228599428496928 0.14395944821783071554 0.26237109907984806911" rpy="-1.5707963267948983344 -3.3355470534782881752e-15 -9.5394697344059988075e-16" />
<geometry>
<mesh filename="package://rover_description/rover_desc/parts/body.stl"/>
</geometry>
</collision>
<inertial>
<origin xyz="-0.0034322859941748047434 0.0020938861086602922335 0.35730795518198049665" rpy="0 0 0"/>
<mass value="14.890136874895455676" />
<inertia ixx="0.43250086301603934968" ixy="2.9721267248896739341e-14"  ixz="1.1704030822239045252e-09" iyy="0.37287690006963231104" iyz="-0.00013013794919542435871" izz="0.68054838135481388051" />
</inertial>
</link>


<link name="left_rocker">
<visual>
<origin xyz="0.07816000000000011827 0.14200000000000037592 0.01800000000000012701" rpy="-1.570796326794896558 -1.5707963267948950037 0" />
<geometry>
<mesh filename="package://rover_description/rover_desc/parts/left_rocker.stl"/>
</geometry>
<material name="left_rocker_material">
<color rgba="0.68235294117647060652 0.33333333333333331483 0.73725490196078435901 1.0"/>
</material>
</visual>
<collision>
<origin xyz="0.07816000000000011827 0.14200000000000037592 0.01800000000000012701" rpy="-1.570796326794896558 -1.5707963267948950037 0" />
<geometry>
<mesh filename="package://rover_description/rover_desc/parts/left_rocker.stl"/>
</geometry>
</collision>
<inertial>
<origin xyz="0.019843209810583496699 -1.0071465883498831317e-10 -0.01259379922047600478" rpy="0 0 0"/>
<mass value="3.1599156804225070339" />
<inertia ixx="0.091997687781411846553" ixy="3.6592889631047604478e-11"  ixz="6.6591014607623069029e-06" iyy="0.0045988888217397697403" iyz="3.1871321967513628805e-13" izz="0.095584816217209864209" />
</inertial>
</link>

<link name="fl_servo">
<visual>
<origin xyz="-0.034073937586584723825 -0.077213843876329818494 0.043400000000000132916" rpy="-1.570796326794896558 -1.5707963267948954478 0" />
<geometry>
<mesh filename="package://rover_description/rover_desc/parts/fl_servo.stl"/>
</geometry>
<material name="fl_servo_material">
<color rgba="0.95294117647058818044 0.79607843137254896693 0.48627450980392156188 1.0"/>
</material>
</visual>
<collision>
<origin xyz="-0.034073937586584723825 -0.077213843876329818494 0.043400000000000132916" rpy="-1.570796326794896558 -1.5707963267948954478 0" />
<geometry>
<mesh filename="package://rover_description/rover_desc/parts/fl_servo.stl"/>
</geometry>
</collision>
<inertial>
<origin xyz="0.0079700947515648021963 0.023817007874858756034 -0.012211397442198006213" rpy="0 0 0"/>
<mass value="0.30095826250826973602" />
<inertia ixx="6.1515020750386716097e-05" ixy="4.1386348707448021383e-07"  ixz="1.2153545413687036965e-06" iyy="5.6400683761713572004e-05" iyz="-7.0967198374895849115e-08" izz="9.1372734015628923228e-05" />
</inertial>
</link>

<link name="fl_steer">
<visual>
<origin xyz="0.056900000000000033884 -0.091013843876329769689 0.06867393758658507652" rpy="-1.570796326794901443 9.7218023302443306324e-16 -5.7863152934901557806e-19" />
<geometry>
<mesh filename="package://rover_description/rover_desc/parts/fl_steer.stl"/>
</geometry>
<material name="fl_steer_material">
<color rgba="0.97254901960784312376 0.52941176470588235947 0.0039215686274509803377 1.0"/>
</material>
</visual>
<collision>
<origin xyz="0.056900000000000033884 -0.091013843876329769689 0.06867393758658507652" rpy="-1.570796326794901443 9.7218023302443306324e-16 -5.7863152934901557806e-19" />
<geometry>
<mesh filename="package://rover_description/rover_desc/parts/fl_steer.stl"/>
</geometry>
</collision>
<inertial>
<origin xyz="0.021796088565620277966 -3.4269795938512981337e-07 -0.022257353183229824228" rpy="0 0 0"/>
<mass value="1.3486655156843314618" />
<inertia ixx="0.0036322882753136629362" ixy="-1.3750609455605709302e-08"  ixz="0.0026697404360839158133" iyy="0.0068253606450100548497" iyz="4.2296529827094503289e-08" izz="0.0034338949276419452987" />
</inertial>
</link>

<link name="fl_motor">
<visual>
<origin xyz="-0.028999999999999998002 0.002999999999999974909 -0.11825000000000004952" rpy="1.570796326794896558 5.421257686680294571e-32 -9.7638531054305158568e-33" />
<geometry>
<mesh filename="package://rover_description/rover_desc/parts/fl_motor.stl"/>
</geometry>
<material name="fl_motor_material">
<color rgba="0.86666666666666669627 0.13333333333333333148 0.13333333333333333148 1.0"/>
</material>
</visual>
<collision>
<origin xyz="-0.028999999999999998002 0.002999999999999974909 -0.11825000000000004952" rpy="1.570796326794896558 5.421257686680294571e-32 -9.7638531054305158568e-33" />
<geometry>
<mesh filename="package://rover_description/rover_desc/parts/fl_motor.stl"/>
</geometry>
</collision>
<inertial>
<origin xyz="0.0081633417621368303818 -0.0080748979523884763937 -0.063711508697810809165" rpy="0 0 0"/>
<mass value="1.1669635249832903678" />
<inertia ixx="0.0014435661258087530319" ixy="2.7173683331507626971e-09"  ixz="5.1318365618333701989e-07" iyy="0.0014456129621376958855" iyz="-2.4540570541830781249e-07" izz="0.00022941596317910245952" />
</inertial>
</link>

<link name="fl_whl">
<visual>
<origin xyz="-0.18104393758658485214 -0.091013843608109823435 0.050899999999998529754" rpy="-1.57079632679489678 -1.570796326794891451 0" />
<geometry>
<mesh filename="package://rover_description/rover_desc/parts/fl_whl.stl"/>
</geometry>
<material name="fl_whl_material">
<color rgba="0.18823529411764705621 0.2313725490196078538 0.58823529411764707842 1.0"/>
</material>
</visual>
<collision>
<origin xyz="-0.18104393758658485214 -0.091013843608109823435 0.050899999999998529754" rpy="-1.57079632679489678 -1.570796326794891451 0" />
<geometry>
<mesh filename="package://rover_description/rover_desc/parts/fl_whl.stl"/>
</geometry>

</collision>
<inertial>
<origin xyz="-7.9178013523293577987e-17 -9.7144514654701197287e-17 -0.0070773280698739971309" rpy="0 0 0"/>
<mass value="1.3365750692679565503" />
<inertia ixx="0.002829424224058673179" ixy="-2.1539453691249887424e-19"  ixz="4.2738442004738362441e-18" iyy="0.002829424224058673179" iyz="8.5390822538103700404e-18" izz="0.0046912485783696094427" />
</inertial>
</link>

<joint name="fl_wheel" type="continuous">
<origin xyz="0.0079999999999995630162 -0.0079999999999979809484 0.023499999999998494316" rpy="3.1415926535897926719 -5.7430720689678564416e-16 2.5563346814631189297" />
<parent link="fl_motor" />
<child link="fl_whl" />
<axis xyz="0 0 1"/>
<limit effort="1" velocity="20" />
<joint_properties friction="12.0"/>
</joint>

<joint name="FL_Motor2Mount" type="fixed">
<origin xyz="0.029500000000000720091 -0.0080000002682209248039 -0.10437000000000032363" rpy="-3.1415926535897926719 1.570796326794891451 0" />
<parent link="fl_steer" />
<child link="fl_motor" />
<axis xyz="0 0 1"/>
<limit effort="1" velocity="20" />
<joint_properties friction="0.0"/>
</joint>

<link name="fl_clamp">
<visual>
<origin xyz="-0.047600000000000530775 -0.11250057860073051086 0.18179393758658513036" rpy="-1.5707963267949001107 2.2947746081961756375e-15 -5.7863152935050374413e-19" />
<geometry>
<mesh filename="package://rover_description/rover_desc/parts/fl_clamp.stl"/>
</geometry>
<material name="fl_clamp_material">
<color rgba="1 0.52156862745098042655 0.10196078431372548878 1.0"/>
</material>
</visual>
<collision>
<origin xyz="-0.047600000000000530775 -0.11250057860073051086 0.18179393758658513036" rpy="-1.5707963267949001107 2.2947746081961756375e-15 -5.7863152935050374413e-19" />
<geometry>
<mesh filename="package://rover_description/rover_desc/parts/fl_clamp.stl"/>
</geometry>
</collision>
<inertial>
<origin xyz="-1.0621386825615530825e-09 -0.021486142739031308113 -0.013953120641351964004" rpy="0 0 0"/>
<mass value="0.023562966261883398073" />
<inertia ixx="5.8649646333848660368e-06" ixy="8.0054195219834950149e-12"  ixz="1.2846874940053395266e-12" iyy="1.1647538922670263761e-06" iyz="-1.2018458141570976938e-10" izz="5.1248936208296153987e-06" />
</inertial>
</link>

<joint name="FL_Clamp2Mount" type="fixed">
<origin xyz="0.10450000000000081446 0.02148673472440049137 -0.11162000000000021904" rpy="-1.3191487418674471279e-15 -1.3225943751717407993e-15 -5.7863152934430677564e-19" />
<parent link="fl_steer" />
<child link="fl_clamp" />
<axis xyz="0 0 1"/>
<limit effort="1" velocity="20" />
<joint_properties friction="0.0"/>
</joint>

<joint name="FL_Steer2Servo" type="revolute">
<origin xyz="0.034599999999999991873 0.013800000000000367528 -0.013499999999999900968" rpy="-1.5707963267943512164 -1.5667839918887107586 1.5707963267946660757" />
<parent link="fl_servo" />
<child link="fl_steer" />
<axis xyz="0 0 1"/>
<limit effort="1" velocity="20" lower="-1.0471975511965976313" upper="1.0471975511965976313"/>
<joint_properties friction="0.0"/>
</joint>

<!-- <gazebo reference="FL_Steer2Servo">
    <provideFeedback>true</provideFeedback>
    <implicitSpringDamper>true</implicitSpringDamper>
    <springStiffness>200.0</springStiffness>
    <springReference>0.0</springReference>
    <friction>0.75</friction>
</gazebo> -->

<joint name="FL_Servo2Rocker" type="fixed">
<origin xyz="0.11223393758658459229 0.21921384387633149893 -0.025399999999999700595" rpy="-7.5158228832025782511e-16 1.4251748903082761431e-15 1.5777218104420229102e-30" />
<parent link="left_rocker" />
<child link="fl_servo" />
<axis xyz="0 0 1"/>
<limit effort="1" velocity="20" />
<joint_properties friction="0.0"/>
</joint>

<link name="bl_servo">
<visual>
<origin xyz="-0.034073937586588359805 0.36121384387633087565 0.043400000000000493738" rpy="-1.570796326794896558 -1.5707963267948950037 0" />
<geometry>
<mesh filename="package://rover_description/rover_desc/parts/bl_servo.stl"/>
</geometry>
<material name="bl_servo_material">
<color rgba="0.95294117647058818044 0.79607843137254896693 0.48627450980392156188 1.0"/>
</material>
</visual>
<collision>
<origin xyz="-0.034073937586588359805 0.36121384387633087565 0.043400000000000493738" rpy="-1.570796326794896558 -1.5707963267948950037 0" />
<geometry>
<mesh filename="package://rover_description/rover_desc/parts/bl_servo.stl"/>
</geometry>
</collision>
<inertial>
<origin xyz="0.007970094751564916688 -0.023817007874858575622 -0.012211397442197985397" rpy="0 0 0"/>
<mass value="0.30095826250826984705" />
<inertia ixx="6.1515020750386743202e-05" ixy="-4.1386348707453214753e-07"  ixz="1.2153545413686098876e-06" iyy="5.6400683761713572004e-05" iyz="7.0967198374668420769e-08" izz="9.1372734015628963885e-05" />
</inertial>
</link>

<link name="bl_steer">
<visual>
<origin xyz="0.056900000000000089395 0.3750138438763308546 0.068673937586589073323" rpy="-1.5707963267948947816 1.0259804808888011719e-15 -2.2516610801147431128e-19" />
<geometry>
<mesh filename="package://rover_description/rover_desc/parts/bl_steer.stl"/>
</geometry>
<material name="bl_steer_material">
<color rgba="1 0.52156862745098042655 0.10196078431372548878 1.0"/>
</material>
</visual>
<collision>
<origin xyz="0.056900000000000089395 0.3750138438763308546 0.068673937586589073323" rpy="-1.5707963267948947816 1.0259804808888011719e-15 -2.2516610801147431128e-19" />
<geometry>
<mesh filename="package://rover_description/rover_desc/parts/bl_steer.stl"/>
</geometry>
</collision>
<inertial>
<origin xyz="0.021796088565502275136 4.2836195762729900594e-07 -0.0222573531832480076" rpy="0 0 0"/>
<mass value="1.3486655156810449796" />
<inertia ixx="0.0036322882752310749199" ixy="8.9151877740356255028e-09"  ixz="0.0026697404360826525009" iyy="0.0068253606450098865815" iyz="-3.3253112102159356026e-08" izz="0.0034338949275451989031" />
</inertial>
</link>

<link name="bl_motor">
<visual>
<origin xyz="-0.028999999999999984124 0.0030000000000000026645 -0.11825000000000003564" rpy="1.570796326794896558 -3.2298776845706547017e-31 -2.3153937587166193837e-32" />
<geometry>
<mesh filename="package://rover_description/rover_desc/parts/bl_motor.stl"/>
</geometry>
<material name="bl_motor_material">
<color rgba="0.86666666666666669627 0.13333333333333333148 0.13333333333333333148 1.0"/>
</material>
</visual>
<collision>
<origin xyz="-0.028999999999999984124 0.0030000000000000026645 -0.11825000000000003564" rpy="1.570796326794896558 -3.2298776845706547017e-31 -2.3153937587166193837e-32" />
<geometry>
<mesh filename="package://rover_description/rover_desc/parts/bl_motor.stl"/>
</geometry>
</collision>
<inertial>
<origin xyz="0.0081633417621368442596 -0.0080748979523884469034 -0.063711508697810809165" rpy="0 0 0"/>
<mass value="1.1669635249832903678" />
<inertia ixx="0.0014435661258087530319" ixy="2.7173683331513843233e-09"  ixz="5.1318365618334856072e-07" iyy="0.0014456129621376954519" iyz="-2.4540570541830273029e-07" izz="0.00022941596317910243241" />
</inertial>
</link>

<link name="bl_whl">
<visual>
<origin xyz="-0.18104393758658796076 0.37501384414455324334 0.050899999999998446487" rpy="-1.570796326794896558 -1.5707963267948921171 0" />
<geometry>
<mesh filename="package://rover_description/rover_desc/parts/bl_whl.stl"/>
</geometry>
<material name="bl_whl_material">
<color rgba="0.18823529411764705621 0.2313725490196078538 0.58823529411764707842 1.0"/>
</material>
</visual>
<collision>
<origin xyz="-0.18104393758658796076 0.37501384414455324334 0.050899999999998446487" rpy="-1.570796326794896558 -1.5707963267948921171 0" />
<geometry>
<mesh filename="package://rover_description/rover_desc/parts/bl_whl.stl"/>
</geometry>
</collision>
<inertial>
<origin xyz="-6.0984259665726272122e-17 -1.1102230246251565404e-16 -0.0070773280698740240191" rpy="0 0 0"/>
<mass value="1.3365750692679563283" />
<inertia ixx="0.0028294242240586723117" ixy="-2.8075497875679871817e-19"  ixz="1.9100519512254011122e-18" iyy="0.0028294242240586740464" iyz="8.3560769281583097021e-18" izz="0.004691248578369607708" />
</inertial>
</link>

<joint name="bl_wheel" type="continuous">
<origin xyz="0.0079999999999999793499 -0.0079999999999998128164 0.023500000000000076383" rpy="3.1415926535897926719 2.4528544646838575776e-16 2.5563346814631637827" />
<parent link="bl_motor" />
<child link="bl_whl" />
<axis xyz="0 0 1"/>
<limit effort="1" velocity="20" />
<joint_properties friction="12.0"/>
</joint>

<joint name="BL_Motor2Mount" type="fixed">
<origin xyz="0.029500000000000331513 -0.0080000002682207305149 -0.10436999999999960198" rpy="-3.1415926535897922278 1.5707963267948943376 0" />
<parent link="bl_steer" />
<child link="bl_motor" />
<axis xyz="0 0 1"/>
<limit effort="1" velocity="20" />
<joint_properties friction="0.0"/>
</joint>

<link name="bl_clamp">
<visual>
<origin xyz="-0.047600000000000003419 0.35352710915193058527 0.18179393758658762836" rpy="-1.5707963267948972241 2.2462499910870153881e-15 -2.0161291737649410925e-19" />
<geometry>
<mesh filename="package://rover_description/rover_desc/parts/bl_clamp.stl"/>
</geometry>
<material name="bl_clamp_material">
<color rgba="1 0.52156862745098042655 0.10196078431372548878 1.0"/>
</material>
</visual>
<collision>
<origin xyz="-0.047600000000000003419 0.35352710915193058527 0.18179393758658762836" rpy="-1.5707963267948972241 2.2462499910870153881e-15 -2.0161291737649410925e-19" />
<geometry>
<mesh filename="package://rover_description/rover_desc/parts/bl_clamp.stl"/>
</geometry>
</collision>
<inertial>
<origin xyz="-1.0621386548059774668e-09 -0.021486142739031488524 -0.01395312064135205421" rpy="0 0 0"/>
<mass value="0.023562966261883144803" />
<inertia ixx="5.8649646333847804864e-06" ixy="8.0054195353524769323e-12"  ixz="1.2846874971607049935e-12" iyy="1.164753892267009859e-06" iyz="-1.2018458138789618317e-10" izz="5.1248936208295408598e-06" />
</inertial>
</link>

<joint name="BL_Clamp2Mount" type="fixed">
<origin xyz="0.10450000000000017608 0.021486734724400657903 -0.11161999999999946964" rpy="4.297839667967753496e-16 5.6655398768737880863e-18 -2.2516610801413402054e-19" />
<parent link="bl_steer" />
<child link="bl_clamp" />
<axis xyz="0 0 1"/>
<limit effort="1" velocity="20" />
<joint_properties friction="0.0"/>
</joint>

<joint name="BL_Steer2Servo" type="revolute">
<origin xyz="0.034600000000000102895 -0.013800000000000173239 -0.013500000000000039746" rpy="-1.5707963267952376185 -1.566783991888712757 1.5707963267956142062" />
<parent link="bl_servo" />
<child link="bl_steer" />
<axis xyz="0 0 1"/>
<limit effort="1" velocity="20" lower="-1.0471975511965976313" upper="1.0471975511965976313"/>
<joint_properties friction="0.0"/>
</joint>

<!-- <gazebo reference="BL_Steer2Servo">
    <provideFeedback>true</provideFeedback>
    <implicitSpringDamper>true</implicitSpringDamper>
    <springStiffness>200.0</springStiffness>
    <springReference>0.0</springReference>
    <friction>0.75</friction>
</gazebo> -->

<joint name="BL_Servo2Rocker" type="fixed">
<origin xyz="0.11223393758658836705 -0.21921384387633077728 -0.025400000000000255707" rpy="-2.7483631710412831567e-15 1.3713746424438999486e-15 0" />
<parent link="left_rocker" />
<child link="bl_servo" />
<axis xyz="0 0 1"/>
<limit effort="1" velocity="20" />
<joint_properties friction="0.0"/>
</joint>

<joint name="l_rocker2body" type="revolute">
<origin xyz="-0.21143228599428551262 0.0019594482178305061559 0.34053109907984824289" rpy="-8.0380829845163244361e-16 1.5707963267948907848 0" />
<parent link="body" />
<child link="left_rocker" />
<axis xyz="0 0 1"/>
<limit effort="1" velocity="20" lower="-0.52359877559829881566" upper="0.52359877559829881566"/>
<joint_properties friction="0.0"/>
</joint>

<gazebo reference="l_rocker2body">
    <provideFeedback>true</provideFeedback>
    <implicitSpringDamper>true</implicitSpringDamper>
    <springStiffness>100.0</springStiffness>
    <springReference>0.0</springReference>
</gazebo>

<link name="right_rocker">
<visual>
<origin xyz="0.078160000000000728893 -0.14199999999999982081 0.39800000000000024247" rpy="1.570796326794896558 1.5707963267948945596 0" />
<geometry>
<mesh filename="package://rover_description/rover_desc/parts/right_rocker.stl"/>
</geometry>
<material name="right_rocker_material">
<color rgba="0.68235294117647060652 0.33333333333333331483 0.73725490196078435901 1.0"/>
</material>
</visual>
<collision>
<origin xyz="0.078160000000000728893 -0.14199999999999982081 0.39800000000000024247" rpy="1.570796326794896558 1.5707963267948945596 0" />
<geometry>
<mesh filename="package://rover_description/rover_desc/parts/right_rocker.stl"/>
</geometry>
</collision>
<inertial>
<origin xyz="0.019749845958477146857 -1.0151601781416275116e-10 -0.012563787207807319835" rpy="0 0 0"/>
<mass value="3.1748536151173403219" />
<inertia ixx="0.092000731965220239328" ixy="3.6644812894457526487e-11"  ixz="8.5409407367578405932e-06" iyy="0.0046077871870401944376" iyz="3.337613462120723989e-13" izz="0.095595491905617502315" />
</inertial>
</link>

<link name="fr_servo">
<visual>
<origin xyz="-0.034073937586587610404 0.077213843876329651961 0.4234000000000001096" rpy="1.570796326794896558 1.5707963267948947816 0" />
<geometry>
<mesh filename="package://rover_description/rover_desc/parts/fr_servo.stl"/>
</geometry>
<material name="fr_servo_material">
<color rgba="0.95294117647058818044 0.79607843137254896693 0.48627450980392156188 1.0"/>
</material>
</visual>
<collision>
<origin xyz="-0.034073937586587610404 0.077213843876329651961 0.4234000000000001096" rpy="1.570796326794896558 1.5707963267948947816 0" />
<geometry>
<mesh filename="package://rover_description/rover_desc/parts/fr_servo.stl"/>
</geometry>
</collision>
<inertial>
<origin xyz="0.0079700947515648403602 -0.023817007874858520111 -0.01221139744219790213" rpy="0 0 0"/>
<mass value="0.30095826250826984705" />
<inertia ixx="6.1515020750386607677e-05" ixy="-4.1386348707453971789e-07"  ixz="1.2153545413685711358e-06" iyy="5.6400683761713395821e-05" iyz="7.0967198374693580295e-08" izz="9.137273401562877415e-05" />
</inertial>
</link>

<link name="fr_steer">
<visual>
<origin xyz="-0.43690000000000006608 -0.091013843876329908467 0.068673937586587685544" rpy="-1.5707963267948976682 -1.6286182669569800446e-15 -2.4337315947146275507e-32" />
<geometry>
<mesh filename="package://rover_description/rover_desc/parts/fr_steer.stl"/>
</geometry>
<material name="fr_steer_material">
<color rgba="1 0.52156862745098042655 0.10196078431372548878 1.0"/>
</material>
</visual>
<collision>
<origin xyz="-0.43690000000000006608 -0.091013843876329908467 0.068673937586587685544" rpy="-1.5707963267948976682 -1.6286182669569800446e-15 -2.4337315947146275507e-32" />
<geometry>
<mesh filename="package://rover_description/rover_desc/parts/fr_steer.stl"/>
</geometry>
</collision>
<inertial>
<origin xyz="-0.021796088565566140716 -4.2836189803607815918e-07 -0.022257353183248288625" rpy="0 0 0"/>
<mass value="1.3486655156810425371" />
<inertia ixx="0.0036322882752310636442" ixy="8.9151874335952450242e-09"  ixz="-0.0026697404360826676797" iyy="0.0068253606450099073982" iyz="3.3253111821837574076e-08" izz="0.0034338949275452283934" />
</inertial>
</link>

<link name="fr_motor">
<visual>
<origin xyz="-0.045000000000000012212 0.0030000000000000026645 -0.11824999999999996625" rpy="1.570796326794896558 1.0103251656619010782e-31 -1.4652627824245612462e-20" />
<geometry>
<mesh filename="package://rover_description/rover_desc/parts/fr_motor.stl"/>
</geometry>
<material name="fr_motor_material">
<color rgba="0.86666666666666669627 0.13333333333333333148 0.13333333333333333148 1.0"/>
</material>
</visual>
<collision>
<origin xyz="-0.045000000000000012212 0.0030000000000000026645 -0.11824999999999996625" rpy="1.570796326794896558 1.0103251656619010782e-31 -1.4652627824245612462e-20" />
<geometry>
<mesh filename="package://rover_description/rover_desc/parts/fr_motor.stl"/>
</geometry>
</collision>
<inertial>
<origin xyz="-0.007836658237863183829 -0.0080748979523884469034 -0.063711508697810725899" rpy="0 0 0"/>
<mass value="1.1669635249832908119" />
<inertia ixx="0.0014435661258087525982" ixy="2.7173683331507382952e-09"  ixz="5.1318365618334231385e-07" iyy="0.0014456129621376950182" iyz="-2.4540570541830696546e-07" izz="0.00022941596317910240531" />
</inertial>
</link>

<link name="fr_whl">
<visual>
<origin xyz="-0.18104393758658596236 0.091013844144441857775 0.43089999999992534274" rpy="1.570796326794896558 1.5707963267944513586 0" />
<geometry>
<mesh filename="package://rover_description/rover_desc/parts/fr_whl.stl"/>
</geometry>
<material name="fr_whl_material">
<color rgba="0.62745098039215685404 0.62745098039215685404 0.62745098039215685404 1.0"/>
</material>
</visual>
<collision>
<origin xyz="-0.18104393758658596236 0.091013844144441857775 0.43089999999992534274" rpy="1.570796326794896558 1.5707963267944513586 0" />
<geometry>
<mesh filename="package://rover_description/rover_desc/parts/fr_whl.stl"/>
</geometry>
</collision>
<inertial>
<origin xyz="-3.7780957575932811979e-17 -9.7144514654701197287e-17 -0.0070773280698740448358" rpy="0 0 0"/>
<mass value="1.336575069267954996" />
<inertia ixx="0.0028294242240586723117" ixy="8.9011910890896127632e-33"  ixz="8.6557311137229842599e-18" iyy="0.0028294242240586705769" iyz="1.8882932990998236513e-18" izz="0.0046912485783696059732" />
</inertial>
</link>

<joint name="fr_wheel" type="continuous">
<origin xyz="-0.0080000000000000626166 -0.0079999999999999793499 0.023500000000000048628" rpy="-3.141592653589793116 -1.2616348761332487262e-27 3.1378367530413813213" />
<parent link="fr_motor" />
<child link="fr_whl" />
<axis xyz="0 0 1"/>
<limit effort="1" velocity="20" />
<joint_properties friction="12.0"/>
</joint>

<joint name="FR_Motor2Mount" type="fixed">
<origin xyz="-0.029500000000063808514 -0.0079999997317199977864 -0.10436999999999974076" rpy="-3.1415926535896825378 -1.5707963267948925612 0" />
<parent link="fr_steer" />
<child link="fr_motor" />
<axis xyz="0 0 1"/>
<limit effort="1" velocity="20" />
<joint_properties friction="0.0"/>
</joint>

<link name="fr_clamp">
<visual>
<origin xyz="-0.33239999999993363744 -0.11250057913722313896 0.18179393758658574098" rpy="-1.5707963267948976682 -5.5927484865492402719e-15 4.5342763853053979933e-32" />
<geometry>
<mesh filename="package://rover_description/rover_desc/parts/fr_clamp.stl"/>
</geometry>
<material name="fr_clamp_material">
<color rgba="1 0.52156862745098042655 0.10196078431372548878 1.0"/>
</material>
</visual>
<collision>
<origin xyz="-0.33239999999993363744 -0.11250057913722313896 0.18179393758658574098" rpy="-1.5707963267948976682 -5.5927484865492402719e-15 4.5342763853053979933e-32" />
<geometry>
<mesh filename="package://rover_description/rover_desc/parts/fr_clamp.stl"/>
</geometry>
</collision>
<inertial>
<origin xyz="1.0621409307631779484e-09 -0.021487327246212065135 -0.013953120641351839104" rpy="0 0 0"/>
<mass value="0.023562966261883321745" />
<inertia ixx="5.8649646333849312583e-06" ixy="8.0054200433861070288e-12"  ixz="-1.2846874875787233356e-12" iyy="1.1647538922670318818e-06" iyz="1.2018458145444898976e-10" izz="5.1248936208296628326e-06" />
</inertial>
</link>

<joint name="FR_Clamp2Mount" type="fixed">
<origin xyz="-0.10450000000006709477 0.021486735260893480293 -0.11161999999999966393" rpy="8.8444140894472082179e-17 3.9641302195922511554e-15 -8.1071766067163712513e-30" />
<parent link="fr_steer" />
<child link="fr_clamp" />
<axis xyz="0 0 1"/>
<limit effort="1" velocity="20" />
<joint_properties friction="0.0"/>
</joint>

<joint name="FR_Steer2Servo" type="revolute">
<origin xyz="0.034600000000000019629 -0.013800000000000034461 -0.013499999999999984235" rpy="-3.1415926535897922278 1.5707963267948945596 0" />
<parent link="fr_servo" />
<child link="fr_steer" />
<axis xyz="0 0 1"/>
<limit effort="1" velocity="20" lower="-1.0471975511965976313" upper="1.0471975511965976313"/>
<joint_properties friction="0.0"/>
</joint>

<!-- <gazebo reference="FR_Steer2Servo">
    <provideFeedback>true</provideFeedback>
    <implicitSpringDamper>true</implicitSpringDamper>
    <springStiffness>200.0</springStiffness>
    <springReference>0.0</springReference>
    <friction>0.75</friction>
</gazebo> -->

<joint name="FR_Servo2Rocker" type="fixed">
<origin xyz="0.11223393758658814501 -0.21921384387633036095 -0.025400000000000616529" rpy="-2.4134538591578045008e-16 -2.0555539217396999166e-17 3.1489024047051702671e-19" />
<parent link="right_rocker" />
<child link="fr_servo" />
<axis xyz="0 0 1"/>
<limit effort="1" velocity="20" />
<joint_properties friction="0.0"/>
</joint>

<link name="br_servo">
<visual>
<origin xyz="-0.034073937586584585047 -0.36121384387633004298 0.42339999999999999858" rpy="1.570796326794896558 1.5707963267948950037 0" />
<geometry>
<mesh filename="package://rover_description/rover_desc/parts/br_servo.stl"/>
</geometry>
<material name="br_servo_material">
<color rgba="0.95294117647058818044 0.79607843137254896693 0.48627450980392156188 1.0"/>
</material>
</visual>
<collision>
<origin xyz="-0.034073937586584585047 -0.36121384387633004298 0.42339999999999999858" rpy="1.570796326794896558 1.5707963267948950037 0" />
<geometry>
<mesh filename="package://rover_description/rover_desc/parts/br_servo.stl"/>
</geometry>
</collision>
<inertial>
<origin xyz="0.007970094751564509028 0.02381700787480783843 -0.012211397442186633366" rpy="0 0 0"/>
<mass value="0.3009582625082701246" />
<inertia ixx="6.1515020750379275759e-05" ixy="4.1386348710015780586e-07"  ixz="1.2153545413628288877e-06" iyy="5.6400683761704518916e-05" iyz="-7.096719839154229646e-08" izz="9.1372734015629858352e-05" />
</inertial>
</link>

<link name="br_steer">
<visual>
<origin xyz="-0.43689999999998418989 0.37501384387626873762 0.068673937586585853676" rpy="-1.5707963267948921171 -1.574818019091989919e-15 -2.67551987683194984e-32" />
<geometry>
<mesh filename="package://rover_description/rover_desc/parts/br_steer.stl"/>
</geometry>
<material name="br_steer_material">
<color rgba="0.97254901960784312376 0.52941176470588235947 0.0039215686274509803377 1.0"/>
</material>
</visual>
<collision>
<origin xyz="-0.43689999999998418989 0.37501384387626873762 0.068673937586585853676" rpy="-1.5707963267948921171 -1.574818019091989919e-15 -2.67551987683194984e-32" />
<geometry>
<mesh filename="package://rover_description/rover_desc/parts/br_steer.stl"/>
</geometry>
</collision>
<inertial>
<origin xyz="-0.021796088565727067543 3.4269791349128553293e-07 -0.022257353183423318754" rpy="0 0 0"/>
<mass value="1.348665515689196237" />
<inertia ixx="0.0036322882753268906364" ixy="-1.3750611663390406009e-08"  ixz="-0.0026697404360926952488" iyy="0.0068253606450268313605" iyz="-4.2296533427855762063e-08" izz="0.0034338949276469890072" />
</inertial>
</link>

<link name="br_motor">
<visual>
<origin xyz="-0.044999999999999998335 0.0030000000000000026645 -0.11825000000000000788" rpy="1.570796326794896558 -1.8202362472477753605e-31 -8.1542138269875287543e-20" />
<geometry>
<mesh filename="package://rover_description/rover_desc/parts/br_motor.stl"/>
</geometry>
<material name="br_motor_material">
<color rgba="0.86666666666666669627 0.13333333333333333148 0.13333333333333333148 1.0"/>
</material>
</visual>
<collision>
<origin xyz="-0.044999999999999998335 0.0030000000000000026645 -0.11825000000000000788" rpy="1.570796326794896558 -1.8202362472477753605e-31 -8.1542138269875287543e-20" />
<geometry>
<mesh filename="package://rover_description/rover_desc/parts/br_motor.stl"/>
</geometry>
</collision>
<inertial>
<origin xyz="-0.0078366582378631699513 -0.0080748979523884469034 -0.06371150869781078141" rpy="0 0 0"/>
<mass value="1.1669635249832903678" />
<inertia ixx="0.0014435661258087528151" ixy="2.7173683331516411629e-09"  ixz="5.13183656183343055e-07" iyy="0.0014456129621376954519" iyz="-2.4540570541830770661e-07" izz="0.00022941596317910245952" />
</inertial>
</link>

<link name="br_whl">
<visual>
<origin xyz="-0.18104393758658479663 -0.37501384360837108911 0.43089999999995631796" rpy="1.570796326794896558 1.5707963267944542451 0" />
<geometry>
<mesh filename="package://rover_description/rover_desc/parts/br_whl.stl"/>
</geometry>
<material name="br_whl_material">
<color rgba="0.18823529411764705621 0.2313725490196078538 0.58823529411764707842 1.0"/>
</material>
</visual>
<collision>
<origin xyz="-0.18104393758658479663 -0.37501384360837108911 0.43089999999995631796" rpy="1.570796326794896558 1.5707963267944542451 0" />
<geometry>
<mesh filename="package://rover_description/rover_desc/parts/br_whl.stl"/>
</geometry>
</collision>
<inertial>
<origin xyz="-2.3005062834584412123e-17 -4.9960036108132044319e-16 -0.0070773280698739338135" rpy="0 0 0"/>
<mass value="1.3365750692679554401" />
<inertia ixx="0.002829424224058673179" ixy="1.2676769905745770879e-33"  ixz="9.2370861885585338964e-19" iyy="0.0028294242240586723117" iyz="7.8547204682554869206e-19" izz="0.004691248578369607708" />
</inertial>
</link>

<joint name="br_wheel" type="continuous">
<origin xyz="-0.0080000000000000071054 -0.0079999999999999793499 0.023499999999999993117" rpy="-3.141592653589793116 -3.3565753444764130465e-30 3.1378367530413666664" />
<parent link="br_motor" />
<child link="br_whl" />
<axis xyz="0 0 1"/>
<limit effort="1" velocity="20" />
<joint_properties friction="12.0"/>
</joint>

<joint name="BR_Motor2Mount" type="fixed">
<origin xyz="-0.029499999999998888223 -0.0079999997317824755871 -0.10437000000000022648" rpy="-3.1415926535896829819 -1.5707963267948921171 0" />
<parent link="br_steer" />
<child link="br_motor" />
<axis xyz="0 0 1"/>
<limit effort="1" velocity="20" />
<joint_properties friction="0.0"/>
</joint>

<link name="br_clamp">
<visual>
<origin xyz="-0.33239999999998193214 0.35352710861543823473 0.18179393758658546343" rpy="-1.5707963267948934494 -1.4953316362921737706e-15 2.3825656186268124474e-33" />
<geometry>
<mesh filename="package://rover_description/rover_desc/parts/br_clamp.stl"/>
</geometry>
<material name="br_clamp_material">
<color rgba="1 0.52156862745098042655 0.10196078431372548878 1.0"/>
</material>
</visual>
<collision>
<origin xyz="-0.33239999999998193214 0.35352710861543823473 0.18179393758658546343" rpy="-1.5707963267948934494 -1.4953316362921737706e-15 2.3825656186268124474e-33" />
<geometry>
<mesh filename="package://rover_description/rover_desc/parts/br_clamp.stl"/>
</geometry>
</collision>
<inertial>
<origin xyz="1.0621408752520267171e-09 -0.021487327246211943704 -0.013953120641351835635" rpy="0 0 0"/>
<mass value="0.023562966261883578484" />
<inertia ixx="5.8649646333849685278e-06" ixy="8.0054200309620513299e-12"  ixz="-1.284687488006020687e-12" iyy="1.1647538922670395051e-06" iyz="1.2018458145652224042e-10" izz="5.1248936208297043372e-06" />
</inertial>
</link>

<joint name="BR_Clamp2Mount" type="fixed">
<origin xyz="-0.10450000000000228551 0.021486735260830752692 -0.11162000000000010802" rpy="1.5329313582824529832e-15 -7.9486382799815655376e-17 2.0257153139395525174e-30" />
<parent link="br_steer" />
<child link="br_clamp" />
<axis xyz="0 0 1"/>
<limit effort="1" velocity="20" />
<joint_properties friction="0.0"/>
</joint>

<joint name="BR_Steer2Servo" type="revolute">
<origin xyz="0.034599999999999603295 0.013799999999938222794 -0.013499999999985107246" rpy="3.1415926535897886751 1.5707963267948961139 0" />
<parent link="br_servo" />
<child link="br_steer" />
<axis xyz="0 0 1"/>
<limit effort="1" velocity="20" lower="-1.0471975511965976313" upper="1.0471975511965976313"/>
<joint_properties friction="0.0"/>
</joint>

<!-- <gazebo reference="BR_Steer2Servo">
    <provideFeedback>true</provideFeedback>
    <implicitSpringDamper>true</implicitSpringDamper>
    <springStiffness>200.0</springStiffness>
    <springReference>0.0</springReference>
    <friction>0.75</friction>
</gazebo> -->

<joint name="BR_Servo2Rocker" type="fixed">
<origin xyz="0.11223393758658470332 0.21921384387633208179 -0.025400000000000005906" rpy="3.1722415169865354398e-16 1.8314944689513809452e-16 3.1489024047051702671e-19" />
<parent link="right_rocker" />
<child link="br_servo" />
<axis xyz="0 0 1"/>
<limit effort="1" velocity="20" />
<joint_properties friction="0.0"/>
</joint>

<joint name="r_rocker2body" type="revolute">
<origin xyz="0.20456771400571505115 0.001959448217830700445 0.34053109907984957516" rpy="-1.5707963267953113373 1.5670404262464796563 1.5707963267944826669" />
<parent link="body" />
<child link="right_rocker" />
<axis xyz="0 0 1"/>
<limit effort="1" velocity="20" lower="-0.52359877559829881566" upper="0.52359877559829881566"/>
<joint_properties friction="0.0"/>
</joint>

<gazebo reference="r_rocker2body">
    <provideFeedback>true</provideFeedback>
    <implicitSpringDamper>true</implicitSpringDamper>
    <springStiffness>500.0</springStiffness>
    <springReference>0.0</springReference>
    <friction>0.75</friction>
</gazebo>

<gazebo reference="fr_whl">
    <material>Gazebo/Black</material>
    <mu1 value="0.8"/>
    <mu2 value="0.8"/>
</gazebo>

<gazebo reference="fl_whl">
    <material>Gazebo/Black</material>
    <mu1 value="0.8"/>
    <mu2 value="0.8"/>
</gazebo>

<gazebo reference="br_whl">
    <material>Gazebo/Black</material>
    <mu1 value="0.8"/>
    <mu2 value="0.8"/>
</gazebo>

<gazebo reference="bl_whl">
    <material>Gazebo/Black</material>
    <mu1 value="0.8"/>
    <mu2 value="0.8"/>
</gazebo>


</robot>
